Workbook

Sheet العيادات
A1: وزارة الصحـة و الســـــكان
A2: الإدارة المركزية لجودة الرعاية الصحية
A3: الادارة العامة لمتابعة المديريات
A4: PHC assessment standards 2025
A7: م | B7: المعيــــــار | E7: التقييم | F7: ملاحظات
A9: إشتراطات عامة:
A10: النظام الصحي والخدمات:
A11: 1 | B11: لافتة توضح إسم الوحدة / المركز في مكان واضح وسليمة و نظيفة.
A12: 2 | B12: لافتة بالخدمات المقدمة في الوحدة / المركز معلنة و محدثة و معتمدة.
A13: 3 | B13: لافتة رئيسية بأسعار الخدمات المقدمة معلنة و محدثة و معتمدة و لها مرجع.
A14: 4 | B14: لافتة موضح بها توزيع وتقسيمات وحدات المبنى الداخلية بالتفصيل كل طابق على حدة .
A15: 5 | B15: لافتة بالمبادرات التى يتم تقديمها بالوحدة / المركز
A16: القيادة والإدارة:
A17: 6 | B17: يوجد هيكل تنظيمي بالمسمى الوظيفى و الأسماء معلن و محدث و معتمد. | F17: الهيكل التنظيمي غير محدث
A18: 7 | B18: يوجد توصيف وظيفي لجميع العاملين و جميع المسميات الوظيفية بالوحدة / المركز.
A19: 8 | B19: جميع العاملين على علم و دراية تامة بالتوصيف الوظيفي .
A20: 9 | B20: نسخة من خطة العمل السنوية ( التشغيلية).
A21: 10 | B21: لافتات فى مكان واضح بمدخل الوحدة / المركز توضح الآتى:  الرؤية – الرسالة – القيم محدثة و معتمدة  حقوق و واجبات المرضى واضحة ومعلنة و محدثة و معتمدة.  ملصقات منع التدخين معلنة و واضحة في جميع أماكن الإنتظار والممرات وغرف الفحص...الخ
A22: 11 | B22: سياسة منع التدخين مطبقة بالنسبة للعاملين و المرضى.
A23: 12 | B23: لافتة بالموضوعات التثقيفية اليومية المقدمة للمرضى على مدار الأسبوع طبقاً للمجموعات المتجانسة.
A24: 13 | B24: مخارج الوحدة / المركز مشار إليها بوضوح من خلال:  خط سير دخول وخروج المرضى  أسهم إسترشادية للوصول إلى العيادة المطلوبة  كل مكان بالوحدة معنون بلافتة توضح نوع الخدمة المقدمة داخله , و اللافتة أعلى الباب و ليس عليه.  أسهم بمخارج الطوارئ و نقاط التجمع. | F24: لا يوجد اسهم بمخارج الطوارئ
A25: تنظيم العمل :
A26: 14 | B26: تواجد جداول عمل تنظيمية معلنة على مدار فترات العمل لجميع العاملين بالوحدة
A27: 15 | B27: تواجد العاملون طبقا لجداول العمل التنظيمية .
A28: 16 | B28: يلتزم جميع العاملين بالزى الخاص بهم .
A29: 17 | B29: يلتزم جميع العاملين بوضع بادج تعريف موضح فيه : الإسم والقسم والصورة | F29: لا يوجد
A30: البنية التحتية العامة بالوحدة / المركز :
A31: 18 | B31: المبنى مطلي و نظيف من الخارج و الداخل
A32: 19 | B32: لا توجد أي قمامة أو أنقاض أو نفايات حول المبنى
A33: 20 | B33: يوجد فرد أمن على بوابة الوحدة / المركز. | F33: لا يوجد فرد امن على بوابة الوحدة
A34: 21 | B34: تجهيزات و أثاث الوحدة / المركز سليم و سهل التنظيف / التطهير.
A35: 22 | B35: جميع النوافذ المطلة على الخارج عليها سلك معدنى ضيق الفتحات و سليم . | F35: لا يوجد
A36: 23 | B36: الوحدة مجهزة لإستقبال المرضى الغير قادرين على الحركة من خلال :  يوجد بالمدخل منحدر  توجد مصعد في المباني متعددة الطوابق  يوجد كرسي متحرك واحد على الأقل عند كل من : (المدخل الرئيسي - غرفة الطوارئ) | F36: لا يوجد مصعد
A37: 24 | B37: يتمتع المبنى من الداخل بما يكفي من الإنارة والتهوية.
A38: 25 | B38: توافر حوض مخصص لغسيل الأيدي بأماكن تقديم الخدمة :  معنون بحوض غسيل الأيدى  مستلزمات غسيل الأيدى  ملصقات اللحظات الخمس و بوستر غسيل الأيدى  ( و فى حالة عدم توافر حوض يوضع بوستر الدلك بالكحول).
A39: 26 | B39: توفر الخصوصية عن طريق :  غلق غرفة الكشف فور دخول المريض  توفير بارافان عند سرير الكشف سهل التنظيف و التطهير طبقاً لتعليمات مكافحة العدوى.  توافر ملاءة لتغطية المريض عند الكشف  النوافذ المطلة مباشرةً على الشوارع أو الساحات العامة، مغلقة بشكل جيد، ومغطاة بستائر ( أو أى وسيلة) لضمان خصوصية المرضى.
A40: التراخيص :
A41: 27 | B41: تداول النفايات | F41: لا يوجد
A42: 28 | B42: المولد الكهربائي إذا كان ذو قدرة و سعة كافية | F42: لا يوجد
A43: 29. ا | B43: المصعد ( إن وُجد) | F43: لا يوجد
...

Sheet مبادرات-البان
A1: المبادرات
A4: م. | B4: مبادرة صحة المراة المصرية | C4: التقـيـيـــــــم | F4: ملاحظات | G4: التقييم
C5: 0 | D5: 1 | E5: 2
A6: 1 | B6: لافتات/ ملصقات تشير بوجود المبادرة داخل الوحدة | C6: لا يوجد | D6: يوجد بحالة سيئة | E6: يوجد بحالة ممتازة
A7: 2 | B7: الإلتزام بزي المبادرات الرسمي | C7: الجميع غير ملتزم | D7: البعض ملتزم | E7: الجميع ملتزم
A8: 3 | B8: أماكن الإنتظار | C8: غير موجود | D8: موجود و غيرصالحة | E8: موجود وصالحة | F8: غير موجود
A9: 4 | B9: الرائدة/المثقفة الصحية تقوم بالتوعية داخل الوحدة مدتها | C9: لا يوجد | D9: < 15 | E9: 15-20دقيقة | F9: غير موجودة
A10: 5 | B10: الرائدة/المثقفة الصحية تقوم بتوعية داخل الوحدة لعدد مواطنين | C10: لا يوجد | D10: < 10 | E10: 10-15مواطن | F10: غير موجودة
A11: 6 | B11: مقارنة عدد حالات التسجيل على السجلات بعدد جلسات التوعية | C11: لا يوجد | D11: موجود لايدري | E11: موجود على دراية
A12: 7 | B12: عدد السيدات في جلسة التوعية داخل الوحدة | C12: لا يتم التوعية | D12: < 10 | E12: 10-15سيدة
A13: 8 | B13: كروت المواطنين | C13: غير موجود | D13: موجود و لا تسلم للمواطن | E13: موجود و تسلم للمواطن
A14: 9 | B14: تسجيل بيانات كروت المواطنين | C14: غير موجودة | D14: موجودة غير كاملة/واضحة | E14: موجودة و كاملة / واضحة
A15: 10 | B15: تاريخ طباعة الكارت | C15: 2019 | D15: 2021 | E15: 2023
A16: 11 | B16: السجلات الورقية مطابقة للمنظومة الإلكترونية | C16: لا توجد سجلات | D16: سجلات غير مطابقة | E16: سجلات مطابقة
A17: 12 | B17: غرفة فحص ذات خصوصية (تنظيم أسرة) | C17: لا يوجد | D17: موجودة عامة | E17: موجودة و بها خصوصية
A18: 13 | B18: دفتر الإحالة للمستشفيات والتغذية الراجعة | C18: لا يوجد | D18: موجود بدون تسجيل تغذية | E18: موجودة و يسجل بها التغذية
A19: 14 | B19: معايرة جهاز ميزان الأطوال | C19: لا يوجد | D19: موجود بدون معايرة | E19: موجود و مطابق
A20: الإجمالى: | G20: =IF(COUNT(G6:G19)=0,"N/A",SUM((G6:G19))/(COUNT((G6:G19))*2)) -> N/A
A24: م. | B24: مبادرة الإكتشاف المبكر لضعف وفقدان السمع | C24: التقـيـيـــــــم | F24: ملاحظات | G24: التقييم
C25: 0 | D25: 1 | E25: 2
A26: 18 | B26: بوسترات- بانرات- إرشادات | C26: لا يوجد | D26: يوجد بحالة سيئة | E26: يوجد بحالة ممتازة
A27: 19 | B27: الإلتزام بزي المبادرات الرسمي | C27: الجميع غير ملتزم | D27: البعض ملتزم | E27: الجميع ملتزم
A28: 20 | B28: غرفة السمعيات بعيدة عن الضوضاء ومجهزة | C28: ضعيف | D28: متوسط | E28: جيد
A29: 21 | B29: فحص الطفل قبل فحص الغده (الطفل هاديء) | C29: لا يتم | D29: يتم
A30: 22 | B30: نظافة البروب من الشمع | C30: غير نظيف | D30: نظيف
A31: 23 | B31: عدد2تمريض مدرب على المبادرة | C31: لا يوجد | D31: يوجد 1 تمريض | E31: يوجد 2 تمريض
A32: 24 | B32: غرفة السمعيات متاحة طول أيام الأسبوع | C32: غير متاح | D32: متاح بعض الأيام | E32: متاح بالكامل
A33: 25 | B33: طريقة معايرة البروب من خلال الأذن الصناعية | C33: لا يطبق | D33: يطبق مرة كل شهر
A34: 26 | B34: التغذية الراجعة للمتغيبين عن الفحص الثاني والإتصال بالوالدين من الممرضة المسؤولة | C34: لا يوجد | D34: موجودة ليس كامل | E34: موجودة و مطابق
A35: 27 | B35: نسبة تطابق فحوصات الغدة مع السمعيات في كل جلسة | C35: غير موجودة | D35: موجود و ليس مطابق | E35: موجود و مطابق
A36: 28 | B36: دفتر الإحالة للمستشفيات والتغذية الراجعة | C36: لا يوجد | D36: موجود بدون تسجيل تغذية | E36: موجودة و يسجل بها التغذية
A37: 29 | B37: سرعة تبليغ الفريق الإشرافي بالأعطال | C37: لا يتم | D37: يتم مع تأخير | E37: يتم فوراً
A38: الإجمالى: | G38: =IF(COUNT(G26:G37)=0,"N/A",SUM((G26:G37))/(COUNT((G26:G37))*2)) -> N/A
A42: م. | B42: مبادرة فحوصات ماقبل الزواج | C42: التقـيـيـــــــم | F42: ملاحظات | G42: التقييم
C43: 0 | D43: 1 | E43: 2
A44: 1 | B44: أسهم إتجاهات للعيادة (لوحة أكريليك) | C44: غير موجود | D44: بعضها موجود | E44: موجود ككل | F44: لا توجد.
A45: 2 | B45: الإلتزام بالزي الرسمى للمبادرات | C45: الجميع غير ملتزم | D45: البعض ملتزم | E45: الجميع ملتزم
A46: 3 | B46: الطابعة الخاصة بالمبادرة | C46: غير موجود | D46: موجود
A47: 4 | B47: غرفة المشورة | C47: لا يوجد | D47: موجود بدون تسجيل | E47: موجودة و مسجل بها التردد
A48: 5 | B48: تسليم كارت المبادرة للمواطن | C48: غير موجود | D48: موجود و غير مكتمل | E48: موجود و مكتمل
...

Sheet الاجمالي
A3: المحافظة : تواريخ التقييم :
A4: إسم المركز / الوحدة : ابن سهلان إسم القائم بالتقييم :
A5: نتيجة التقييم : | G5: =E54 -> #ERROR!
C8: م | D8: البــــند | E8: النسبة المئوية
C9: 1 | D9: الإشتراطات العامة | E9: ='العيادات'!F50 -> N/A
C10: 2 | D10: تقييم و مراقبة أداء الخدمات الصحية المقدمة بالمنشأة | E10: ='العيادات'!F67 -> N/A
C11: 3 | D11: السلامة البيئية | E11: ='العيادات'!F90 -> N/A
C12: 4 | D12: اللجان | E12: ='العيادات'!F95 -> N/A
C13: 5 | D13: السياسات و الإجراءات / السجلات التمريضية | E13: ='العيادات'!F103 -> N/A
C14: 6 | D14: أدلة العمل / البروتوكولات | E14: ='العيادات'!F109 -> N/A
C15: 7 | D15: القوائم بالعيادات | E15: ='العيادات'!F120 -> N/A
C16: 8 | D16: التسجيل الطبى | E16: ='العيادات'!F140 -> N/A
C17: 9 | D17: الطوارئ | E17: ='العيادات'!F174 -> N/A
C18: 10 | D18: غرفة التطعيمات | E18: ='العيادات'!F193 -> N/A
C19: 11 | D19: عيادة طب الأسرة | E19: ='العيادات'!F206 -> N/A
C20: 12 | D20: عيادة IMCI | E20: ='العيادات'!F213 -> N/A
C21: 13 | D21: عيادة رعاية الأمومة ( الحوامل) | E21: ='العيادات'!F224 -> N/A
C22: 14 | D22: متابعة الأطفال | E22: ='العيادات'!F234 -> N/A
C23: 15 | D23: تنظيم الأسرة / النسا | E23: ='العيادات'!F250 -> N/A
C24: 16 | D24: عيادة الأسنان | E24: ='العيادات'!F262 -> N/A
C25: 17 | D25: ركن الإرواء | E25: ='العيادات'!F268 -> N/A
C26: 18 | D26: الصيدلية | E26: ='العيادات'!F291 -> N/A
C27: 19 | D27: المعمل | E27: ='العيادات'!F320 -> N/A
C28: 20 | D28: الأشعة | E28: ='العيادات'!F345 -> N/A
C29: 21 | D29: غرفة التثقيف الصحى | E29: ='العيادات'!F352 -> N/A
C30: 22 | D30: التعقيم | E30: ='العيادات'!F367 -> N/A
C31: 23 | D31: وحدة غسيل المفروشات | E31: ='العيادات'!F377 -> N/A
C32: 24 | D32: سكن الفريق الطبى | E32: ='العيادات'!F381 -> N/A
C33: 25 | D33: السطح | E33: ='العيادات'!F386 -> N/A
C34: 26 | D34: خزان المياه | E34: ='العيادات'!F392 -> N/A
C35: 27 | D35: النفايات | E35: ='العيادات'!F406 -> N/A
C36: 28 | D36: المخازن | E36: ='العيادات'!F423 -> N/A
C37: 29 | D37: شئون العاملين | E37: ='العيادات'!F429 -> N/A
C38: 30 | D38: إدارة معلومات | E38: ='العيادات'!F435 -> N/A
C39: 31 | D39: مكافحة العدوى | E39: ='العيادات'!F453 -> N/A
C40: 32 | D40: النظافة | E40: ='العيادات'!F463 -> N/A
C41: 33 | D41: العلاج الطبيعى | E41: ='العيادات'!F501 -> N/A
C42: 34 | D42: اجمالي تقييم غرفة المشورة | E42: ='العيادات'!H560 -> 0.75
C43: المبادرات والالبان
C44: 35 | D44: صحة المرأة المصرية | E44: ='مبادرات-البان'!G20 -> N/A
...

Sheet dont delete or edit
B1: هذه المعادلة لا يتم حذفها او التعديل بها للحفاظ على المعادلات الحسابية
A2: 0
A3: 1
A4: 2
